2023-11-09 23:10:01,105 INFO    MainThread:20688 [internal.py:wandb_internal():86] W&B internal server running at pid: 20688, started at: 2023-11-09 23:10:01.105902
2023-11-09 23:10:01,107 INFO    WriterThread:20688 [datastore.py:open_for_write():85] open: C:\Users\nazero\Desktop\link_dl-main\link_dl-main\_02_homeworks\_03_fashion_mnist\wandb\run-20231109_231000-rwpqprx1\run-rwpqprx1.wandb
2023-11-09 23:10:01,107 DEBUG   SenderThread:20688 [sender.py:send():380] send: header
2023-11-09 23:10:01,107 DEBUG   SenderThread:20688 [sender.py:send():380] send: run
2023-11-09 23:10:01,589 ERROR   SenderThread:20688 [internal_api.py:execute():370] 401 response executing GraphQL.
2023-11-09 23:10:01,590 ERROR   SenderThread:20688 [internal_api.py:execute():371] {"errors":[{"message":"user is not logged in","path":["upsertBucket"],"extensions":{"code":"PERMISSION_ERROR"}}],"data":{"upsertBucket":null}}
2023-11-09 23:10:01,591 ERROR   SenderThread:20688 [sender.py:send_run():979] The API key you provided is either invalid or missing.  If the `WANDB_API_KEY` environment variable is set, make sure it is correct. Otherwise, to resolve this issue, you may try running the 'wandb login --relogin' command. If you are using a local server, make sure that you're using the correct hostname. If you're not sure, you can try logging in again using the 'wandb login --relogin --host [hostname]' command.(Error 401: Unauthorized)
Traceback (most recent call last):
  File "C:\Users\nazero\anaconda3\Lib\site-packages\wandb\sdk\lib\retry.py", line 131, in __call__
    result = self._call_fn(*args, **kwargs)
             ^^^^^^^^^^^^^^^^^^^^^^^^^^^^^^
  File "C:\Users\nazero\anaconda3\Lib\site-packages\wandb\sdk\internal\internal_api.py", line 366, in execute
    return self.client.execute(*args, **kwargs)  # type: ignore
           ^^^^^^^^^^^^^^^^^^^^^^^^^^^^^^^^^^^^
  File "C:\Users\nazero\anaconda3\Lib\site-packages\wandb\vendor\gql-0.2.0\wandb_gql\client.py", line 52, in execute
    result = self._get_result(document, *args, **kwargs)
             ^^^^^^^^^^^^^^^^^^^^^^^^^^^^^^^^^^^^^^^^^^^
  File "C:\Users\nazero\anaconda3\Lib\site-packages\wandb\vendor\gql-0.2.0\wandb_gql\client.py", line 60, in _get_result
    return self.transport.execute(document, *args, **kwargs)
           ^^^^^^^^^^^^^^^^^^^^^^^^^^^^^^^^^^^^^^^^^^^^^^^^^
  File "C:\Users\nazero\anaconda3\Lib\site-packages\wandb\sdk\lib\gql_request.py", line 59, in execute
    request.raise_for_status()
  File "C:\Users\nazero\anaconda3\Lib\site-packages\requests\models.py", line 1021, in raise_for_status
    raise HTTPError(http_error_msg, response=self)
requests.exceptions.HTTPError: 401 Client Error: Unauthorized for url: https://api.wandb.ai/graphql

During handling of the above exception, another exception occurred:

Traceback (most recent call last):
  File "C:\Users\nazero\anaconda3\Lib\site-packages\wandb\sdk\internal\sender.py", line 977, in send_run
    self._init_run(run, config_value_dict)
  File "C:\Users\nazero\anaconda3\Lib\site-packages\wandb\sdk\internal\sender.py", line 1015, in _init_run
    server_run, inserted, server_messages = self._api.upsert_run(
                                            ^^^^^^^^^^^^^^^^^^^^^
  File "C:\Users\nazero\anaconda3\Lib\site-packages\wandb\apis\normalize.py", line 73, in wrapper
    raise err
  File "C:\Users\nazero\anaconda3\Lib\site-packages\wandb\apis\normalize.py", line 41, in wrapper
    return func(*args, **kwargs)
           ^^^^^^^^^^^^^^^^^^^^^
  File "C:\Users\nazero\anaconda3\Lib\site-packages\wandb\sdk\internal\internal_api.py", line 2008, in upsert_run
    response = self.gql(
               ^^^^^^^^^
  File "C:\Users\nazero\anaconda3\Lib\site-packages\wandb\sdk\internal\internal_api.py", line 338, in gql
    ret = self._retry_gql(
          ^^^^^^^^^^^^^^^^
  File "C:\Users\nazero\anaconda3\Lib\site-packages\wandb\sdk\lib\retry.py", line 147, in __call__
    retry_timedelta_triggered = check_retry_fn(e)
                                ^^^^^^^^^^^^^^^^^
  File "C:\Users\nazero\anaconda3\Lib\site-packages\wandb\util.py", line 965, in check_retry_fn
    return fallback_retry_fn(e)
           ^^^^^^^^^^^^^^^^^^^^
  File "C:\Users\nazero\anaconda3\Lib\site-packages\wandb\util.py", line 896, in no_retry_auth
    raise AuthenticationError(
wandb.errors.AuthenticationError: The API key you provided is either invalid or missing.  If the `WANDB_API_KEY` environment variable is set, make sure it is correct. Otherwise, to resolve this issue, you may try running the 'wandb login --relogin' command. If you are using a local server, make sure that you're using the correct hostname. If you're not sure, you can try logging in again using the 'wandb login --relogin --host [hostname]' command.(Error 401: Unauthorized)
2023-11-09 23:10:01,603 DEBUG   HandlerThread:20688 [handler.py:handle_request():146] handle_request: shutdown
2023-11-09 23:10:01,603 INFO    HandlerThread:20688 [handler.py:finish():866] shutting down handler
2023-11-09 23:10:02,116 INFO    WriterThread:20688 [datastore.py:close():294] close: C:\Users\nazero\Desktop\link_dl-main\link_dl-main\_02_homeworks\_03_fashion_mnist\wandb\run-20231109_231000-rwpqprx1\run-rwpqprx1.wandb
2023-11-09 23:10:02,610 INFO    SenderThread:20688 [sender.py:finish():1536] shutting down sender
